#VRML_SIM R2023b utf8

EXTERNPROTO "https://raw.githubusercontent.com/cyberbotics/webots/R2023b/projects/objects/trees/protos/BigSassafras.proto"
EXTERNPROTO "https://raw.githubusercontent.com/cyberbotics/webots/R2023b/projects/objects/trees/protos/Cypress.proto"
EXTERNPROTO "https://raw.githubusercontent.com/cyberbotics/webots/R2023b/projects/appearances/protos/DryMud.proto"
EXTERNPROTO "https://raw.githubusercontent.com/cyberbotics/webots/R2023b/projects/objects/trees/protos/Oak.proto"
EXTERNPROTO "https://raw.githubusercontent.com/cyberbotics/webots/R2023b/projects/objects/trees/protos/Pine.proto"
EXTERNPROTO "https://raw.githubusercontent.com/cyberbotics/webots/R2023b/projects/appearances/protos/Rubber.proto"
EXTERNPROTO "https://raw.githubusercontent.com/cyberbotics/webots/R2023b/projects/objects/trees/protos/SimpleTree.proto"
EXTERNPROTO "https://raw.githubusercontent.com/cyberbotics/webots/R2023b/projects/objects/backgrounds/protos/TexturedBackground.proto"
EXTERNPROTO "https://raw.githubusercontent.com/cyberbotics/webots/R2023b/projects/objects/backgrounds/protos/TexturedBackgroundLight.proto"
EXTERNPROTO "https://raw.githubusercontent.com/cyberbotics/webots/R2023b/projects/objects/floors/protos/UnevenTerrain.proto"
EXTERNPROTO "https://raw.githubusercontent.com/cyberbotics/webots/R2023b/projects/appearances/protos/ScuffedPlastic.proto"
EXTERNPROTO "https://raw.githubusercontent.com/cyberbotics/webots/R2023b/projects/appearances/protos/Pcb.proto"

WorldInfo {
}
Viewpoint {
  orientation -0.6476914668767251 -0.2772672478557838 0.7096609310097008 3.731467477028815
  position 9.373599494915068 16.43945349650073 34.690562326675675
}
TexturedBackground {
}
TexturedBackgroundLight {
}
Robot {
  translation 9.15375398924405 20.48841122086445 3.6956746667115197
  rotation 0.020771198907207217 0.05539080485793312 0.9982486744459758 -1.5816524265421466
  children [
    DistanceSensor {
      translation 0.500001 -1.61 0
      rotation 0 0 1 -1.5707953071795862
      children [
        DEF ds Shape {
          appearance ReflectiveSurface {
          }
          geometry Box {
            size 0.05 0.05 0.05
          }
        }
      ]
      name "ds2"
      boundingObject USE ds
      physics Physics {
        mass 1
      }
      lookupTable [
        0 0 0
        1 1000 0
      ]
    }
    DistanceSensor {
      translation -0.53 -1.63 0
      rotation 0 0 1 -1.5707953071795862
      children [
        DEF ds Shape {
          appearance ReflectiveSurface {
          }
          geometry Box {
            size 0.05 0.05 0.05
          }
        }
      ]
      name "ds1"
      boundingObject USE ds
      physics Physics {
        mass 1
      }
      lookupTable [
        0 0 0
        1 1000 0
      ]
    }
    Solid {
      translation -0.58 4.58824e-07 0.34
      rotation 1 0 0 -1.5707953071795862
      children [
        Shape {
          appearance Pcb {
          }
          geometry Cylinder {
            height 3
            radius 0.05
          }
        }
      ]
      name "solid(4)"
    }
    Solid {
      translation 0.47 4.58824e-07 0.34
      rotation 1 0 0 -1.5707953071795862
      children [
        Shape {
          appearance Pcb {
          }
          geometry Cylinder {
            height 3
            radius 0.05
          }
        }
      ]
      name "solid(5)"
    }
    DEF base Shape {
      appearance ScuffedPlastic {
        colorOverride 0.333333 0.666667 0
      }
      geometry DEF Base Box {
        size 1.5 3.2 0.5
      }
    }
    DEF WHEEL1 HingeJoint {
      jointParameters HingeJointParameters {
        position 506.25910806412134
        anchor 0.75 -0.96 -0.53
      }
      device [
        RotationalMotor {
          name "wheel1"
          maxTorque 40
        }
      ]
      endPoint Solid {
        translation 0.7500056668700354 -0.9600462603340493 -0.5300382201266938
        rotation -0.6974937234133136 0.16430566605719174 -0.697499931111491 2.8158936692493475
        children [
          DEF wheel Shape {
            appearance Rubber {
              type "dotted"
            }
            geometry Cylinder {
              height 0.5
              radius 0.5
              subdivision 50
            }
          }
        ]
        boundingObject USE wheel
        physics DEF phy1 Physics {
          mass 1
        }
        linearVelocity -0.00030480955470598076 0.02444275432831559 -0.0011566681914136838
        angularVelocity -0.04828429832059801 -3.987522540415173 0.3047595199423075
      }
    }
    DEF WHEEL2 HingeJoint {
      jointParameters HingeJointParameters {
        position 442.3763983032126
        anchor -0.75 -0.96 -0.53
      }
      device [
        RotationalMotor {
          name "wheel2"
          maxTorque 40
        }
      ]
      endPoint Solid {
        translation -0.7500224218090552 -0.9598917514392824 -0.5301605202270769
        rotation -0.6914444340960745 -0.2094356388686998 -0.6914053136397048 3.5544044892515
        children [
          DEF wheel Shape {
            appearance Rubber {
              type "dotted"
            }
            geometry Cylinder {
              height 0.5
              radius 0.5
              subdivision 50
            }
          }
        ]
        name "solid(1)"
        boundingObject USE wheel
        physics USE phy1
        linearVelocity 0.0006678739980300806 0.02370963004725857 -0.010425154743536696
        angularVelocity -0.04828175783148324 -3.9876410247224006 0.3048181179208412
      }
    }
    DEF WHEEL3 HingeJoint {
      jointParameters HingeJointParameters {
        position 486.60851944090956
        anchor 0.75 0.96 -0.53
      }
      device [
        RotationalMotor {
          name "wheel3"
          maxTorque 40
        }
      ]
      endPoint Solid {
        translation 0.7499912770032688 0.9599166198380779 -0.5300220411082701
        rotation 0.7019993646885468 0.11990915130536912 0.7020104610403627 2.902934817897513
        children [
          DEF wheel Shape {
            appearance Rubber {
              type "dotted"
            }
            geometry Cylinder {
              height 0.5
              radius 0.5
              subdivision 50
            }
          }
        ]
        name "solid(2)"
        boundingObject USE wheel
        physics USE phy1
        linearVelocity -0.0003416146087135614 0.024220243527705198 -0.0021196097345612705
        angularVelocity -0.04829933109274271 -3.9876390335002108 0.3048416410350901
      }
    }
    DEF WHEEL4 HingeJoint {
      jointParameters HingeJointParameters {
        position 423.7784597937544
        anchor -0.75 0.96 -0.53
      }
      device [
        RotationalMotor {
          name "wheel4"
          maxTorque 40
        }
      ]
      endPoint Solid {
        translation -0.7499943566352494 0.9600456659061417 -0.5299573749214652
        rotation -0.7020565436672949 -0.11926665155706344 -0.7020627289069672 3.3790010048206565
        children [
          DEF wheel Shape {
            appearance Rubber {
              type "dotted"
            }
            geometry Cylinder {
              height 0.5
              radius 0.5
              subdivision 50
            }
          }
        ]
        name "solid(3)"
        boundingObject USE wheel
        physics USE phy1
        linearVelocity -0.00017732751932179067 0.02353478609353411 -0.011475284383345226
        angularVelocity -0.04829623224152854 -3.987495651489587 0.3047738236017655
      }
    }
  ]
  boundingObject USE base
  physics USE phy1
  controller "my_controller"
  linearVelocity 3.65114920872068e-05 0.02756988734212784 -0.006166261560345586
  angularVelocity -0.006607545983931611 0.0004847675923721655 -0.00033179491649406565
}
DEF forest Solid {
  children [
    Pine {
      translation -15.62 20.85 1.15
      name "pine tree(6)"
    }
    Pine {
      translation -15.62 -10.45 1.15
      name "pine tree(5)"
    }
    Pine {
      translation 11.67 -10.45 1.45
      name "pine tree(3)"
    }
    Pine {
      translation 20.49 -10.45 2.81
      name "pine tree(4)"
    }
    Pine {
      translation 11.67 15.84 1.88
      name "pine tree(2)"
    }
    Pine {
      translation -4.35 9.25 2.22
      name "pine tree(1)"
    }
    Pine {
      translation -4.35 -3.53 2.18
    }
    SimpleTree {
      translation 0 0 3
    }
    SimpleTree {
      translation 6 0 3
      name "tree(1)"
    }
    SimpleTree {
      translation 6 10 3
      name "tree(2)"
    }
    SimpleTree {
      translation 16 15 3
      name "tree(3)"
    }
    SimpleTree {
      translation -16 -15 1.8
      name "tree(4)"
    }
    SimpleTree {
      translation 16 -15 3
      name "tree(5)"
    }
    SimpleTree {
      translation 5 -22 2
      name "tree(6)"
    }
    SimpleTree {
      translation -15 -22 2
      name "tree(7)"
    }
    SimpleTree {
      translation -9 22 2
      name "tree(8)"
    }
    SimpleTree {
      translation -18 16 2.5
      name "tree(9)"
    }
    SimpleTree {
      translation -22 -3 2
      name "tree(10)"
    }
    SimpleTree {
      translation 10 -8 3
      name "tree(11)"
    }
    SimpleTree {
      translation -5 -8 2.3
      name "tree(12)"
    }
    SimpleTree {
      translation 1 -17 2
      name "tree(13)"
    }
    Oak {
      translation 14.94 0 3.24
    }
    Oak {
      translation 20 -5.97 3.28
      name "oak tree(1)"
    }
    Oak {
      translation 15.97 -10.75 3.02
      name "oak tree(2)"
    }
    Oak {
      translation 15.97 11.04 3.07
      name "oak tree(3)"
    }
    Oak {
      translation -24.52 6.27 2.46
      name "oak tree(4)"
    }
    Oak {
      translation -12.06 2.39 2.09
      name "oak tree(6)"
    }
    Oak {
      translation -13.84 10.96 2.09
      name "oak tree(7)"
    }
    Oak {
      translation -2.97 18.97 1.79
      name "oak tree(8)"
    }
    Oak {
      translation 0.35 13.07 2.24
      name "oak tree(9)"
    }
    Oak {
      translation -9.22 15.64 2.72
      name "oak tree(5)"
    }
    Oak {
      translation 7.46 20.45 2.43
      name "oak tree(10)"
    }
    Oak {
      translation 16.74 21.4 2.43
      name "oak tree(11)"
    }
    BigSassafras {
      translation -11.82 -13.71 1.72
    }
    BigSassafras {
      translation -21.32 -8.95 1.72
      name "sassafras tree(1)"
    }
    BigSassafras {
      translation 19.67 7.95 3.44
      name "sassafras tree(2)"
    }
    BigSassafras {
      translation 19.67 -1.13 2.97
      name "sassafras tree(3)"
    }
    BigSassafras {
      translation 21.66 -19.93 2.97
      name "sassafras tree(4)"
    }
    BigSassafras {
      translation 9.84 -19.93 2.64
      name "sassafras tree(5)"
    }
    BigSassafras {
      translation -6.69 -19.93 1.29
      name "sassafras tree(6)"
    }
    BigSassafras {
      translation -16.82 -5.16 2.98
      name "sassafras tree(7)"
    }
    BigSassafras {
      translation -16.82 8.12 2.98
      name "sassafras tree(8)"
    }
    BigSassafras {
      translation -21.82 21.14 2.98
      name "sassafras tree(9)"
    }
    BigSassafras {
      translation 1.95 21.14 2.63
      name "sassafras tree(10)"
    }
    Cypress {
      translation -11.36 0 1.96
    }
    Cypress {
      translation -14.16 5.78 2.06
      name "cypress tree(1)"
    }
    Cypress {
      translation 20.42 15.8 3.01
      name "cypress tree(2)"
    }
    Cypress {
      translation 21.87 20.79 3.01
      name "cypress tree(3)"
    }
    Cypress {
      translation 11.51 1.81 3.01
      name "cypress tree(4)"
    }
    Cypress {
      translation 2.77 -10.75 2.51
      name "cypress tree(5)"
    }
    Cypress {
      translation -2.24 -21.57 1.87
      name "cypress tree(6)"
    }
    Cypress {
      translation 15.22 -21.57 2.5
      name "cypress tree(7)"
    }
    Cypress {
      translation 6.61 -15.53 2.8
      name "cypress tree(8)"
    }
    Cypress {
      translation -11.26 5.51 2.26
      name "cypress tree(9)"
    }
  ]
}
UnevenTerrain {
  appearance DryMud {
  }
}
DEF Border Solid {
  translation 0 0 3.9
  children [
    Solid {
      translation 9.589423659841419e-05 -25.200083043824915 -0.37012660413189025
      rotation -0.058290865016834746 0.722136093370251 0.689290677223725 0.001064263081622104
      children [
        DEF border Shape {
          appearance DryMud {
          }
          geometry Box {
            size 49 1 3
          }
        }
      ]
      name "border1"
      boundingObject USE border
      physics DEF phy1 Physics {
        mass 1
      }
      linearVelocity 0.00014495549826824573 -9.734010994588971e-05 0.00016717969675204359
      angularVelocity 0.00031711571087370086 0.0002943953169841524 -0.00023026564403366137
    }
    Solid {
      translation -5.7839445395981695e-09 25.530000041646467 -0.37021957628162383
      rotation 0.017583635301710056 -0.2864503988036631 0.9579337058454508 9.438940519982046e-07
      children [
        DEF border Shape {
          appearance DryMud {
          }
          geometry Box {
            size 49 1 3
          }
        }
      ]
      name "border2"
      boundingObject USE border
      physics USE phy1
      linearVelocity 4.5191480377180024e-08 -3.2539479983604033e-07 -9.650677003482935e-08
      angularVelocity -1.296753102636334e-07 2.1554724041736187e-06 -7.207728800246444e-06
    }
    Solid {
      translation 25.53 0 -0.37
      rotation 0 0 1 1.5708
      children [
        DEF border Shape {
          appearance DryMud {
          }
          geometry Box {
            size 49 1 3
          }
        }
      ]
      name "border3"
      boundingObject USE border
    }
    Solid {
      translation -25.5301 1.57462e-05 -0.37021957309661113
      rotation 5.1580022398749126e-05 -9.550089548459884e-05 0.9999999941095401 1.569814080916819
      children [
        DEF border Shape {
          appearance DryMud {
          }
          geometry Box {
            size 49 1 3
          }
        }
      ]
      name "border4"
      boundingObject USE border
      physics USE phy1
      linearVelocity 0 0 -1.2139210974737436e-07
    }
  ]
  name "solid(1)"
}
